Workbook

Sheet Cover
B2: AI Accounting Roll-Up — Margin Transformation Model
B3: Quick-draft v1.0 · Operator track · Italian SMB accounting studio archetype
B5: Purpose
B6: Show typical accounting practice margin baseline (~20% EBITDA) and
B7: the realistic post-AI margin envelope (24-30% slow / 28-34% base / 32-38% aggressive).
B9: Archetype: Italian SMB studio, 15 FTE, ~€1.95M revenue, 75% recurring book.
B10: Consistent with Tier-1 target profile in the main research memo addendum.
B13: Model contents
B14: Cover | C14: this tab
B15: Inputs | C15: all hardcoded assumptions (FTE, comp, rates, AI productivity gains)
B16: Operating | C16: FTE & cost build, revenue build, baseline vs post-AI
B17: PL | C17: baseline P&L vs post-AI P&L side by side
B18: Scenarios | C18: slow / base / aggressive AI deployment
B19: Outputs | C19: margin transformation summary + roll-up math
B20: Sources | C20: references and benchmarks
B22: Switches
B23: Scenario (1=Slow / 2=Base / 3=Aggressive) | C23: 2
B24: Display unit | C24: € thousands (K)
B25: Currency | C25: EUR
B28: Version log
B29: v1.0 · 21 May 2026 · Initial quick-draft margin model

Sheet Inputs
B1: Inputs — all hardcoded assumptions live here
B2: Italian SMB accounting studio archetype · 15 FTE · €1.95M revenue baseline
B3: All figures in € K unless stated
B5: 1. Headcount baseline (FTE)
B6: Role | C6: Unit | D6: FTE | E6: Loaded comp/FTE (€K) | F6: Annual cost (€K)
B7: Partners / owner (sole prop equiv.) | C7: FTE | D7: 1.5 | E7: 185 | F7: =D7*E7
B8: Senior / managers | C8: FTE | D8: 3 | E8: 90 | F8: =D8*E8
B9: Mid-level staff (Mid) | C9: FTE | D9: 5 | E9: 70 | F9: =D9*E9
B10: Junior staff (Staff) | C10: FTE | D10: 4 | E10: 45 | F10: =D10*E10
B11: Admin / paraprofessional | C11: FTE | D11: 1.5 | E11: 50 | F11: =D11*E11
B12: Total headcount baseline | D12: =SUM(D7:D11) | F12: =SUM(F7:F11)
B14: 2. Revenue assumptions
B15: Revenue per FTE baseline (€K) | C15: €K | D15: 130
B16: Total revenue baseline | D16: =D12*D15
B18: Revenue mix
B19: Recurring (bookkeeping, payroll, VAT, monthly) | C19: % | D19: 0.75
B20: Advisory & consulting | C20: % | D20: 0.15
B21: One-off / project | C21: % | D21: 0.1
B22: Total | D22: =SUM(D19:D21)
B24: 3. Non-people opex (baseline, % of revenue)
B25: Software / licences (TeamSystem, Zucchetti, etc.) | C25: % | D25: 0.04
B26: Office rent & utilities | C26: % | D26: 0.05
B27: Marketing / BD | C27: % | D27: 0.02
B28: Training & professional subscriptions | C28: % | D28: 0.015
B29: Travel & entertainment | C29: % | D29: 0.01
B30: Insurance / professional indemnity | C30: % | D30: 0.035
B31: Other admin / overhead | C31: % | D31: 0.04
B32: Total non-people opex (% revenue) | D32: =SUM(D25:D31)
B34: 4. AI productivity gains by role (time freed, %)
B35: Role | D35: Slow (Yr 1) | E35: Base (Yr 2) | F35: Aggressive (Yr 2)
B36: Partners / senior | D36: 0.05 | E36: 0.1 | F36: 0.15
B37: Senior / managers | D37: 0.1 | E37: 0.2 | F37: 0.28
B38: Mid-level staff | D38: 0.15 | E38: 0.25 | F38: 0.35
B39: Junior staff | D39: 0.2 | E39: 0.35 | F39: 0.5
B40: Admin / paraprofessional | D40: 0.2 | E40: 0.4 | F40: 0.55
B42: 5. AI tooling cost increase (€K/year)
B43: Incremental AI software / IDP / copilot licenses | C43: €K | D43: 35 | E43: 60 | F43: 90
B45: 6. How freed capacity is used (% to revenue vs % to cost cut)
B46: Slow scenario — % to revenue uplift | C46: % | D46: 0.3 | E46: % to cost cut | F46: 0.7
B47: Base scenario — % to revenue uplift | C47: % | D47: 0.5 | E47: % to cost cut | F47: 0.5
...

Sheet Operating
B1: Operating Model — Revenue & Cost Build
B2: All figures in € K
D5: Baseline | E5: Slow AI | F5: Base AI | G5: Aggressive AI
B7: Headcount (FTE) — after AI deployment
B8: Partners / senior | C8: FTE | D8: =Inputs!D7 | E8: =Inputs!D7*(1-Inputs!D36*Inputs!F46) | F8: =Inputs!D7*(1-Inputs!E36*Inputs!F47) | G8: =Inputs!D7*(1-Inputs!F36*Inputs!F48)
B9: Senior / managers | C9: FTE | D9: =Inputs!D8 | E9: =Inputs!D8*(1-Inputs!D37*Inputs!F46) | F9: =Inputs!D8*(1-Inputs!E37*Inputs!F47) | G9: =Inputs!D8*(1-Inputs!F37*Inputs!F48)
B10: Mid-level staff | C10: FTE | D10: =Inputs!D9 | E10: =Inputs!D9*(1-Inputs!D38*Inputs!F46) | F10: =Inputs!D9*(1-Inputs!E38*Inputs!F47) | G10: =Inputs!D9*(1-Inputs!F38*Inputs!F48)
B11: Junior staff | C11: FTE | D11: =Inputs!D10 | E11: =Inputs!D10*(1-Inputs!D39*Inputs!F46) | F11: =Inputs!D10*(1-Inputs!E39*Inputs!F47) | G11: =Inputs!D10*(1-Inputs!F39*Inputs!F48)
B12: Admin / paraprofessional | C12: FTE | D12: =Inputs!D11 | E12: =Inputs!D11*(1-Inputs!D40*Inputs!F46) | F12: =Inputs!D11*(1-Inputs!E40*Inputs!F47) | G12: =Inputs!D11*(1-Inputs!F40*Inputs!F48)
B13: Total FTE | D13: =SUM(D8:D12) | E13: =SUM(E8:E12) | F13: =SUM(F8:F12) | G13: =SUM(G8:G12)
B15: Revenue build
B16: Revenue/FTE baseline (€K) | C16: €K | D16: =Inputs!D15
B17: Weighted capacity freed (% of total labor capacity) | C17: % | D17: 0 | E17: =SUMPRODUCT(Inputs!D36:Inputs!D40,Inputs!F7:Inputs!F11)/Inputs!F12 | F17: =SUMPRODUCT(Inputs!E36:Inputs!E40,Inputs!F7:Inputs!F11)/Inputs!F12 | G17: =SUMPRODUCT(Inputs!F36:Inputs!F40,Inputs!F7:Inputs!F11)/Inputs!F12
B18: % of freed capacity used for revenue uplift | C18: % | D18: 0 | E18: =Inputs!D46 | F18: =Inputs!D47 | G18: =Inputs!D48
B19: Revenue volume uplift (capacity → clients) | C19: % | D19: 0 | E19: =E17*E18 | F19: =F17*F18 | G19: =G17*G18
B20: Price uplift | C20: % | D20: 0 | E20: =Inputs!D51 | F20: =Inputs!E51 | G20: =Inputs!F51
B21: Total revenue | D21: =Inputs!D16 | E21: =Inputs!D16*(1+E19)*(1+E20) | F21: =Inputs!D16*(1+F19)*(1+F20) | G21: =Inputs!D16*(1+G19)*(1+G20)
B23: Cost build
B24: Partners / senior — labor cost | C24: €K | D24: =Inputs!F7 | E24: =E7*Inputs!E7 | F24: =F7*Inputs!E7 | G24: =G7*Inputs!E7
B25: Senior / managers — labor cost | C25: €K | D25: =Inputs!F8 | E25: =E8*Inputs!E8 | F25: =F8*Inputs!E8 | G25: =G8*Inputs!E8
B26: Mid-level staff — labor cost | C26: €K | D26: =Inputs!F9 | E26: =E9*Inputs!E9 | F26: =F9*Inputs!E9 | G26: =G9*Inputs!E9
B27: Junior staff — labor cost | C27: €K | D27: =Inputs!F10 | E27: =E10*Inputs!E10 | F27: =F10*Inputs!E10 | G27: =G10*Inputs!E10
B28: Admin / paraprofessional — labor cost | C28: €K | D28: =Inputs!F11 | E28: =E11*Inputs!E11 | F28: =F11*Inputs!E11 | G28: =G11*Inputs!E11
B29: Total labor cost | D29: =SUM(D24:D28) | E29: =SUM(E24:E28) | F29: =SUM(F24:F28) | G29: =SUM(G24:G28)
B31: Non-people opex (% of revenue) | C31: % | D31: =Inputs!D32 | E31: =Inputs!D32 | F31: =Inputs!D32 | G31: =Inputs!D32
B32: Non-people opex (€K) | C32: €K | D32: =D21*D31 | E32: =E21*E31 | F32: =F21*F31 | G32: =G21*G31
B33: Incremental AI tooling cost (€K) | C33: €K | D33: 0 | E33: =Inputs!D43 | F33: =Inputs!E43 | G33: =Inputs!F43
B35: EBITDA | D35: =D21-D29-D32-D33 | E35: =E21-E29-E32-E33 | F35: =F21-F29-F32-F33 | G35: =G21-G29-G32-G33
B36: EBITDA margin | D36: =D35/D21 | E36: =E35/E21 | F36: =F35/F21 | G36: =G35/G21
B38: Owner comp normalization (addback) | C38: €K | D38: 65 | E38: =D38 | F38: =D38 | G38: =D38
B39: Adjusted EBITDA | D39: =D35+D38 | E39: =E35+E38 | F39: =F35+F38 | G39: =G35+G38
B40: Adjusted EBITDA margin | D40: =D39/D21 | E40: =E39/E21 | F40: =F39/F21 | G40: =G39/G21

Sheet PL
B1: P&L — Baseline vs Post-AI (Base scenario)
B2: Side-by-side P&L showing margin transformation. All figures in € K.
D5: Baseline | E5: Post-AI (Base) | F5: Δ
B7: Revenue
B8: Recurring (bookkeeping, payroll, VAT) | C8: €K | D8: =Operating!D21*Inputs!D19 | E8: =Operating!F21*Inputs!D19 | F8: =E8-D8
B9: Advisory & consulting | C9: €K | D9: =Operating!D21*Inputs!D20 | E9: =Operating!F21*Inputs!D20 | F9: =E9-D9
B10: One-off / project | C10: €K | D10: =Operating!D21*Inputs!D21 | E10: =Operating!F21*Inputs!D21 | F10: =E10-D10
B11: Total revenue | D11: =SUM(D8:D10) | E11: =SUM(E8:E10) | F11: =E11-D11
B13: Operating costs
B14: Partners / senior — labor cost | C14: €K | D14: =Operating!D24 | E14: =Operating!F24 | F14: =E14-D14
B15: Senior / managers — labor cost | C15: €K | D15: =Operating!D25 | E15: =Operating!F25 | F15: =E15-D15
B16: Mid-level staff — labor cost | C16: €K | D16: =Operating!D26 | E16: =Operating!F26 | F16: =E16-D16
B17: Junior staff — labor cost | C17: €K | D17: =Operating!D27 | E17: =Operating!F27 | F17: =E17-D17
B18: Admin / paraprofessional — labor cost | C18: €K | D18: =Operating!D28 | E18: =Operating!F28 | F18: =E18-D18
B19: Total labor cost | D19: =SUM(D14:D18) | E19: =SUM(E14:E18) | F19: =E19-D19
B20: Labor as % of revenue | C20: % | D20: =D19/D11 | E20: =E19/E11 | F20: =E20-D20
B22: Software / licences (TeamSystem, Zucchetti, etc.) | C22: €K | D22: =D11*Inputs!D25 | E22: =E11*Inputs!D25 | F22: =E22-D22
B23: Office rent & utilities | C23: €K | D23: =D11*Inputs!D26 | E23: =E11*Inputs!D26 | F23: =E23-D23
B24: Marketing / BD | C24: €K | D24: =D11*Inputs!D27 | E24: =E11*Inputs!D27 | F24: =E24-D24
B25: Training & professional subscriptions | C25: €K | D25: =D11*Inputs!D28 | E25: =E11*Inputs!D28 | F25: =E25-D25
B26: Travel & entertainment | C26: €K | D26: =D11*Inputs!D29 | E26: =E11*Inputs!D29 | F26: =E26-D26
B27: Insurance / professional indemnity | C27: €K | D27: =D11*Inputs!D30 | E27: =E11*Inputs!D30 | F27: =E27-D27
B28: Other admin / overhead | C28: €K | D28: =D11*Inputs!D31 | E28: =E11*Inputs!D31 | F28: =E28-D28
B29: Incremental AI tooling | C29: €K | D29: 0 | E29: =Inputs!E43 | F29: =E29-D29
B30: Total non-people opex | D30: =SUM(D22:D29) | E30: =SUM(E22:E29) | F30: =E30-D30
B32: EBITDA | D32: =D11-D19-D30 | E32: =E11-E19-E30 | F32: =E32-D32
B33: EBITDA margin | D33: =D32/D11 | E33: =E32/E11 | F33: =E33-D33
B35: Owner comp normalization addback | C35: €K | D35: =Operating!D38 | E35: =Operating!F38
B36: Adjusted EBITDA (what PE pays for) | D36: =D32+D35 | E36: =E32+E35 | F36: =E36-D36
B37: Adjusted EBITDA margin | D37: =D36/D11 | E37: =E36/E11 | F37: =E37-D37

Sheet Scenarios
B1: Scenarios — Slow / Base / Aggressive AI deployment
B2: Comparison of margin envelope across three AI deployment paths
D5: Baseline | E5: Slow AI | F5: Base AI | G5: Aggressive AI
B7: Headline metrics
B8: Total revenue (€K) | D8: =Operating!D21 | E8: =Operating!E21 | F8: =Operating!F21 | G8: =Operating!G21
B9: Total FTE | D9: =Operating!D13 | E9: =Operating!E13 | F9: =Operating!F13 | G9: =Operating!G13
B10: Total labor cost (€K) | D10: =Operating!D29 | E10: =Operating!E29 | F10: =Operating!F29 | G10: =Operating!G29
B11: Labor as % of revenue | D11: =Operating!D29/Operating!D21 | E11: =Operating!E29/Operating!E21 | F11: =Operating!F29/Operating!F21 | G11: =Operating!G29/Operating!G21
B12: Non-people opex (€K) | D12: =Operating!D32 | E12: =Operating!E32 | F12: =Operating!F32 | G12: =Operating!G32
B13: Incremental AI tooling (€K) | D13: =Operating!D33 | E13: =Operating!E33 | F13: =Operating!F33 | G13: =Operating!G33
B14: EBITDA (€K) | D14: =Operating!D35 | E14: =Operating!E35 | F14: =Operating!F35 | G14: =Operating!G35
B15: EBITDA margin | D15: =Operating!D36 | E15: =Operating!E36 | F15: =Operating!F36 | G15: =Operating!G36
B16: Adjusted EBITDA (€K) | D16: =Operating!D39 | E16: =Operating!E39 | F16: =Operating!F39 | G16: =Operating!G39
B17: Adjusted EBITDA margin | D17: =Operating!D40 | E17: =Operating!E40 | F17: =Operating!F40 | G17: =Operating!G40
B19: Δ vs baseline (margin & abs EBITDA)
B20: Δ Adj EBITDA margin (pp) | D20: 0 | E20: =E17-D17 | F20: =F17-D17 | G20: =G17-D17
B21: Δ Adj EBITDA absolute (€K) | D21: 0 | E21: =E16-D16 | F21: =F16-D16 | G21: =G16-D16
B22: Δ Adj EBITDA % (vs baseline) | D22: 0 | E22: =E16/D16-1 | F22: =F16/D16-1 | G22: =G16/D16-1
B24: Notes on scenarios
B25: Slow | C25: Year 1 of deployment. 30% of freed capacity → revenue, 70% → cost cut. Conservative AI gains.
B26: Base | C26: Year 2 full deployment. 50/50 split. Realistic mid-case for disciplined operator.
B27: Aggressive | C27: Year 2-3, growth-first. 70% capacity → revenue, 30% → cost cut. Requires sales engine.

Sheet Outputs
B1: Outputs — Margin Transformation & Roll-Up Math
B2: Single-firm transformation × roll-up math = platform value creation
B5: Single firm — margin transformation
D6: Baseline | E6: Slow AI | F6: Base AI | G6: Aggressive AI
B7: Revenue (€K) | D7: =Operating!D21 | E7: =Operating!E21 | F7: =Operating!F21 | G7: =Operating!G21
B8: Adjusted EBITDA (€K) | D8: =Operating!D39 | E8: =Operating!E39 | F8: =Operating!F39 | G8: =Operating!G39
B9: Adjusted EBITDA margin | D9: =Operating!D40 | E9: =Operating!E40 | F9: =Operating!F40 | G9: =Operating!G40
B11: Platform roll-up math (8 firms acquired + base AI)
B12: Number of firms in platform | C12: # | D12: 8
B13: Avg revenue per firm (€K) | D13: =Operating!D21
B14: Platform revenue baseline (€K) | D14: =D12*Operating!D21
B15: Platform revenue post-AI base (€K) | D15: =D12*Operating!F21
B17: Platform Adj EBITDA baseline (€K) | D17: =D12*Operating!D39
B18: Platform Adj EBITDA post-AI base (€K) | D18: =D12*Operating!F39
B19: Δ EBITDA from AI (€K) | D19: =D18-D17
B21: Valuation impact (entry vs exit multiple arbitrage)
B22: Entry multiple (avg, bolt-on) | C22: x | D22: 5
B23: Exit multiple (platform-quality) | C23: x | D23: 9
B25: Entry EV (8 firms @ baseline EBITDA × entry mult) | D25: =D22*D17
B26: Exit EV (post-AI EBITDA × exit mult) | D26: =D23*D18
B27: EV creation (€K) | D27: =D26-D25
B28: EV creation as multiple of entry EV | D28: =D26/D25
B30: Decomposition: where does EV creation come from?
B31: From multiple arbitrage (entry vs exit at same EBITDA) | D31: =(D23-D22)*D17
B32: From AI-driven EBITDA growth (at exit multiple) | D32: =(D18-D17)*D23

Sheet Sources
B1: Sources & Benchmarks
B3: Tier | C3: Reference / claim
B4: Benchmark | C4: Services overlay: 60-75% labor as % revenue; 15-30% EBITDA margin baseline for services firms (skill: services overlay)
B5: T3 | C5: Poe Group Advisors — accounting practice EBITDA multiples 4-8x small, 6-12x platform-quality
B6: T3 | C6: Sofer Advisors — recurring revenue >80% adds 0.2-0.4x to multiple
B7: T3 | C7: Madras Accountancy — annual PE deal volume in accounting: 22 (2023) → 65 (2024) → 100+ (2025)
B8: T2 | C8: MGI Worldwide — Italian/Polish accounting firms balance reform, digital change and consolidation
B9: T2 | C9: Wolters Kluwer — Agentic AI and the future-ready accounting firm
B10: T3 | C10: Truewind / Karbon — AI bookkeeping productivity benchmarks: 25-40% gain in document IDP and reconciliation tasks
B11: T2 | C11: Sovos / Avalara / EDICOM — Polish KSeF mandate Feb 2026 (large), April 2026 (all)
B12: T2 | C12: Aventis Advisors — CEE median EV/EBITDA 6.7x vs 9.4x EU ex-CEE
B13: T2 | C13: Eurofound (via CBI) — CEE labor costs ~40% below Western Europe
B14: Internal | C14: Italian SMB studio archetype: 15 FTE / €1.95M rev / 20% baseline EBITDA / 23% adjusted EBITDA — synthesis of services overlay + industry benchmarks
