Workbook
Name ScenarioSwitch: Cover!$C$16

Sheet Cover
B2: PROJECT LEDGER
B3: Buy-and-build roll-up of accounting vendors & firms across PL / IT / CY, with AI overlay
B5: Model version: v1.0 | Currency: EUR (thousands) | Periodicity: Annual FY26–FY30 | Author: Founder (Viktar D.)
B7: STRATEGIC THESIS
B8: • Acquire 8–14 small accounting firms and niche bookkeeping software vendors over 5 years across PL/IT/CY
B9: • Pay 3–6x EBITDA on entry (fragmented long-tail; aging owners; sub-€2M revenue firms)
B10: • Integrate on common AI-powered tech stack (OCR, auto-categorization, agent-style review)
B11: • Drive EBITDA margin from typical 10–15% to 25–35% via automation + shared services
B12: • Exit Year 5–7 to strategic (Visma, TeamSystem, Zucchetti, Sage) or PE secondary at 8–12x EBITDA
B13: • Multiple arbitrage spread = ~5–6x EBITDA at exit per €1 invested; targeted IRR 25–35%
B16: SCENARIO SWITCH (cell C16): 1=Base, 2=Bull, 3=Bear | C16: 1
B18: TAB GUIDE
B19: Checks | C19: Integrity checks: BS balances, NI ties, cash ties
B20: Inputs | C20: All hardcoded assumptions (blue cells)
B21: Country Mix | C21: PL/IT/CY market sizing & acquisition funnel
B22: M&A Schedule | C22: Deal-by-deal pipeline with EV/EBITDA/synergy math
B23: Operating | C23: Bottom-up consolidated revenue and EBITDA build
B24: IS | C24: Income Statement
B25: BS | C25: Balance Sheet
B26: CF | C26: Cash Flow Statement (indirect method)
B27: Debt | C27: Acquisition financing tranches and amortization
B28: Scenarios | C28: Base / Bull / Bear assumption deltas
B29: Sensitivity | C29: Exit multiple × organic growth → IRR/MoIC
B30: 100-Day Plan | C30: Day-by-day execution Gantt with owners & deliverables
... B32: Sources | C32: All data sources with URLs

Sheet Checks
B2: INTEGRITY CHECKS
B4: Check | C4: FY26 | D4: FY27 | E4: FY28 | F4: FY29 | G4: FY30
B5: BS balance: Assets − (Liab + Equity) | C5: ='BS'!C25-'BS'!C40 | D5: =BS!D25-BS!D40 | E5: =BS!E25-BS!E40 | F5: =BS!F25-BS!F40 | G5: =BS!G25-BS!G40
B6: Cash check: CF closing cash − BS cash | C6: =CF!C30-BS!C7 | D6: =CF!D30-BS!D7 | E6: =CF!E30-BS!E7 | F6: =CF!F30-BS!F7 | G6: =CF!G30-BS!G7
B7: NI tie: IS net income − CF NI | C7: =IS!C20-CF!C5 | D7: =IS!D20-CF!D5 | E7: =IS!E20-CF!E5 | F7: =IS!F20-CF!F5 | G7: =IS!G20-CF!G5
B9: ALL CHECKS MUST RETURN 0. Conditional formatting: red if non-zero.

Sheet Inputs
B2: INPUTS & ASSUMPTIONS
B3: Blue = hardcoded inputs. Black = computed. Source notes column E.
B5: Section | C5: Value | D5: Unit | E5: Source / Rationale
B6: MACRO & FX
B7: Reporting currency | C7: EUR | E7: Base currency for consolidation
B8: Reporting unit | C8: Thousands | E8: All values in EUR '000 unless stated
B9: FX: EUR/PLN (avg FY26) | C9: 4.3 | D9: PLN | E9: NBP avg 2025-26; flat assumption
B10: FX: EUR/EUR (avg) | C10: 1 | D10: EUR | E10: Italy & Cyprus are EUR
B11: Corp tax rate PL (CIT) | C11: 0.19 | D11: % | E11: PL CIT 19% (9% small CIT possible)
B12: Corp tax rate IT (IRES+IRAP) | C12: 0.279 | D12: % | E12: IRES 24% + IRAP ~3.9% = ~27.9% effective
B13: Corp tax rate CY | C13: 0.125 | D13: % | E13: Cyprus headline 12.5% (Pillar 2: 15% min for large groups)
B14: Holdco effective tax rate | C14: 0.2 | D14: % | E14: Blended weighted by mix; CY holdco can lower further
B15: CAPITAL & FINANCING
B16: Seed equity raised (closed Day 1) | C16: 250 | D16: €k | E16: Lean seed €50–250k; we use upper bound
B17: Seed extension (Day 90, on traction) | C17: 750 | D17: €k | E17: Bridge to Series A — angel/strategic
B18: Series A (Month 9, acquisition capital) | C18: 6000 | D18: €k | E18: PE/sponsor for first 2 deals + WC
B19: Acquisition debt ratio (% of EV) | C19: 0.4 | D19: % | E19: European mid-market: 35–45% senior debt typical
B20: Acquisition debt rate (EURIBOR + 600 bps) | C20: 0.085 | D20: % | E20: EURIBOR ~2.5% + 600 bps senior margin = ~8.5%
B21: Debt tenor (years) | C21: 5 | D21: yrs | E21: Bullet or amortizing — model uses 5y bullet for term loan
B22: M&A PIPELINE & MULTIPLES
B23: Acquisitions Year 1 (FY26) | C23: 2 | D23: deals | E23: Founder + 1 FTE M&A; PL anchor + CY toehold
B24: Acquisitions Year 2 (FY27) | C24: 3 | D24: deals | E24: Add IT entry (1) + PL bolt-on (2)
B25: Acquisitions Year 3 (FY28) | C25: 3 | D25: deals | E25: Steady cadence — 1 per geo
B26: Acquisitions Year 4 (FY29) | C26: 3 | D26: deals | E26: Continued cadence; scale operations
B27: Acquisitions Year 5 (FY30) | C27: 3 | D27: deals | E27: Pre-exit; build to size
B28: Avg target revenue (acquired co) | C28: 800 | D28: €k | E28: Sub-€2M sweet spot; PL skews smaller, IT larger
B29: Avg target EBITDA margin (pre-deal) | C29: 0.12 | D29: % | E29: Typical mom-and-pop bookkeeping firm: 10–15%
B30: Entry EV/EBITDA multiple (Base) | C30: 4.5 | D30: x | E30: PL 3–5x; IT 5–8x; CY 3–5x; weighted ~4.5x
B31: Exit EV/EBITDA multiple (Base, Y5) | C31: 10 | D31: x | E31: European SMB SaaS at scale; Visma 2023 secondary implied ~22x on group
B32: Transaction costs (% of EV) | C32: 0.05 | D32: % | E32: Lawyers, accountants, advisors
B33: Earnout deferred (% of EV) | C33: 0.2 | D33: % | E33: Standard 20% earnout over 2–3 years
B34: OPERATING DRIVERS
B35: Organic revenue growth (acquired cohort) | C35: 0.08 | D35: % | E35: 8% blended; SMB churn-adjusted
B36: EBITDA uplift from AI/automation (per year) | C36: 0.04 | D36: ppts | E36: OCR + auto-categorization + cross-sell; +400 bps/yr first 2 yrs
B37: EBITDA margin cap (mature) | C37: 0.3 | D37: % | E37: Reasonable steady-state for hybrid services+SaaS
B38: Holdco SG&A (annual, FY26 baseline) | C38: 480 | D38: €k | E38: Founder + 2 FTE + tools (3-5 head HQ + tooling)
B39: Holdco SG&A growth rate (per year) | C39: 0.2 | D39: % | E39: Hires for finance/legal as deals scale
B40: Integration cost (% of target rev, one-time) | C40: 0.1 | D40: % | E40: Tech migration + rebrand + HR
B41: D&A (% of revenue) | C41: 0.03 | D41: % | E41: Goodwill not amortized under IFRS; D&A from tech capex
B42: Capex (% of revenue, organic) | C42: 0.04 | D42: % | E42: Platform engineering + integrations
...

Sheet Country Mix
B2: MARKET SIZING & ACQUISITION FUNNEL
B3: Sources: agent research (Eurostat + national stat offices + industry associations); see Sources tab
B5: Metric | C5: Poland (PL) | D5: Italy (IT) | E5: Cyprus (CY) | F5: Total / Notes
B6: Number of registered accounting/bookkeeping firms | C6: 52847 | D6: 127000 | E6: 800 | F6: PL + IT = 99% of universe
B7: Estimated annual accounting market size (€M) | C7: 275 | D7: 1350 | E7: 53 | F7: PL+IT+CY ~€1.68B addressable
B8: Number of SMBs (<50 employees, '000) | C8: 2400 | D8: 4200 | E8: 50 | F8: Eurostat SBA factsheets
B9: E-invoicing mandate status | C9: KSeF Feb 2026 | D9: SdI since 2019 | E9: EU 2030 ViDA | F9: Major demand driver
B10: Avg local accountant salary (€/yr fully loaded) | C10: 18000 | D10: 38000 | E10: 32000 | F10: Glassdoor + national assoc
B11: Local M&A multiple range (EV/EBITDA) | C11: 4 | D11: 6.5 | E11: 4 | F11: PL 3–5x; IT 5–8x; CY 3–5x — midpoint shown
B12: Long-tail acquisition targets (revenue <€2M) | C12: 8500 | D12: 22000 | E12: 250 | F12: Estimate (~16% of universe)
B13: Realistic 5Y acquisition target | C13: 6 | D13: 5 | E13: 3 | F13: Conservative funnel (~0.07% of long-tail)
B16: ENTRY SEQUENCE & RATIONALE
B17: Phase 1 — Poland (Months 0–9) | C17: KSeF mandate creates forced-buyer dynamics; lowest multiples; 8.5k long-tail targets; entry through 1 anchor firm acquisition + 1 software vendor bolt-on
B18: Phase 2 — Cyprus (Months 3–6) | C18: Set up holdco for IP and tax optimization; small acquisition for tax/audit nicheservice — used as M&A/finance hub. Pillar 2 may erode advantage; still favorable for sub-€750M groups.
B19: Phase 3 — Italy (Months 9–18) | C19: Higher multiples but proven consolidation precedent (TeamSystem, Zucchetti). Enter via 1 commercialista acquisition with strong digital practice. Defer until we have €5M+ to deploy.

Sheet M&A Schedule
B2: DEAL-BY-DEAL PIPELINE
B3: All amounts in €'000. Targets are profile sketches; replace with real LOIs as pipeline materializes.
B5: Codename | C5: Geo | D5: FY | E5: Target rev (€k) | F5: Tgt EBITDA margin | G5: Tgt EBITDA (€k) | H5: Entry multiple | I5: EV (€k) | J5: Equity (€k) | K5: Debt (€k) | L5: Earnout (€k)
B6: LEDGER-1 (PL anchor) | C6: PL | D6: FY26 | E6: 1200 | F6: 0.13 | G6: =E6*F6 | H6: 4 | I6: =G6*H6 | J6: =I6*(1-Inputs!$C$20)*(1-Inputs!$C$21) | K6: =I6*Inputs!$C$20*(1-Inputs!$C$21) | L6: =I6*Inputs!$C$21
B7: LEDGER-2 (CY hub) | C7: CY | D7: FY26 | E7: 400 | F7: 0.18 | G7: =E7*F7 | H7: 4 | I7: =G7*H7 | J7: =I7*(1-Inputs!$C$20)*(1-Inputs!$C$21) | K7: =I7*Inputs!$C$20*(1-Inputs!$C$21) | L7: =I7*Inputs!$C$21
B8: LEDGER-3 (PL software) | C8: PL | D8: FY27 | E8: 900 | F8: 0.2 | G8: =E8*F8 | H8: 5 | I8: =G8*H8 | J8: =I8*(1-Inputs!$C$20)*(1-Inputs!$C$21) | K8: =I8*Inputs!$C$20*(1-Inputs!$C$21) | L8: =I8*Inputs!$C$21
B9: LEDGER-4 (IT anchor) | C9: IT | D9: FY27 | E9: 1500 | F9: 0.15 | G9: =E9*F9 | H9: 6.5 | I9: =G9*H9 | J9: =I9*(1-Inputs!$C$20)*(1-Inputs!$C$21) | K9: =I9*Inputs!$C$20*(1-Inputs!$C$21) | L9: =I9*Inputs!$C$21
B10: LEDGER-5 (PL bolt-on) | C10: PL | D10: FY27 | E10: 700 | F10: 0.12 | G10: =E10*F10 | H10: 4 | I10: =G10*H10 | J10: =I10*(1-Inputs!$C$20)*(1-Inputs!$C$21) | K10: =I10*Inputs!$C$20*(1-Inputs!$C$21) | L10: =I10*Inputs!$C$21
B11: LEDGER-6 (IT commercialista) | C11: IT | D11: FY28 | E11: 1100 | F11: 0.14 | G11: =E11*F11 | H11: 6 | I11: =G11*H11 | J11: =I11*(1-Inputs!$C$20)*(1-Inputs!$C$21) | K11: =I11*Inputs!$C$20*(1-Inputs!$C$21) | L11: =I11*Inputs!$C$21
B12: LEDGER-7 (PL payroll niche) | C12: PL | D12: FY28 | E12: 800 | F12: 0.18 | G12: =E12*F12 | H12: 5 | I12: =G12*H12 | J12: =I12*(1-Inputs!$C$20)*(1-Inputs!$C$21) | K12: =I12*Inputs!$C$20*(1-Inputs!$C$21) | L12: =I12*Inputs!$C$21
B13: LEDGER-8 (CY audit bolt-on) | C13: CY | D13: FY28 | E13: 500 | F13: 0.2 | G13: =E13*F13 | H13: 4.5 | I13: =G13*H13 | J13: =I13*(1-Inputs!$C$20)*(1-Inputs!$C$21) | K13: =I13*Inputs!$C$20*(1-Inputs!$C$21) | L13: =I13*Inputs!$C$21
B14: LEDGER-9 (IT bolt-on) | C14: IT | D14: FY29 | E14: 1300 | F14: 0.15 | G14: =E14*F14 | H14: 6.5 | I14: =G14*H14 | J14: =I14*(1-Inputs!$C$20)*(1-Inputs!$C$21) | K14: =I14*Inputs!$C$20*(1-Inputs!$C$21) | L14: =I14*Inputs!$C$21
B15: LEDGER-10 (PL ERP niche) | C15: PL | D15: FY29 | E15: 1000 | F15: 0.16 | G15: =E15*F15 | H15: 5 | I15: =G15*H15 | J15: =I15*(1-Inputs!$C$20)*(1-Inputs!$C$21) | K15: =I15*Inputs!$C$20*(1-Inputs!$C$21) | L15: =I15*Inputs!$C$21
B16: LEDGER-11 (CY corp services) | C16: CY | D16: FY29 | E16: 600 | F16: 0.22 | G16: =E16*F16 | H16: 4.5 | I16: =G16*H16 | J16: =I16*(1-Inputs!$C$20)*(1-Inputs!$C$21) | K16: =I16*Inputs!$C$20*(1-Inputs!$C$21) | L16: =I16*Inputs!$C$21
B17: LEDGER-12 (IT scale-up) | C17: IT | D17: FY30 | E17: 2000 | F17: 0.18 | G17: =E17*F17 | H17: 7 | I17: =G17*H17 | J17: =I17*(1-Inputs!$C$20)*(1-Inputs!$C$21) | K17: =I17*Inputs!$C$20*(1-Inputs!$C$21) | L17: =I17*Inputs!$C$21
... B19: LEDGER-14 (PL e-invoice) | C19: PL | D19: FY30 | E19: 1100 | F19: 0.17 | G19: =E19*F19 | H19: 5.5 | I19: =G19*H19 | J19: =I19*(1-Inputs!$C$20)*(1-Inputs!$C$21) | K19: =I19*Inputs!$C$20*(1-Inputs!$C$21) | L19: =I19*Inputs!$C$21
B22: TOTAL | E22: =SUM(E6:E19) | F22: =SUM(F6:F19) | G22: =SUM(G6:G19) | H22: =SUM(H6:H19) | I22: =SUM(I6:I19) | J22: =SUM(J6:J19) | K22: =SUM(K6:K19) | L22: =SUM(L6:L19)
B25: DEPLOYED CAPITAL BY YEAR
B26: Year | C26: # deals | D26: Total EV (€k) | E26: Equity (€k) | F26: Debt (€k) | G26: Earnout (€k)
B27: FY26 | C27: =COUNTIF(D6:D19,"FY26") | D27: =SUMIF($D$6:$D$19,"FY26",I$6:I$19) | E27: =SUMIF($D$6:$D$19,"FY26",J$6:J$19) | F27: =SUMIF($D$6:$D$19,"FY26",K$6:K$19) | G27: =SUMIF($D$6:$D$19,"FY26",L$6:L$19)
B28: FY27 | C28: =COUNTIF(D6:D19,"FY27") | D28: =SUMIF($D$6:$D$19,"FY27",I$6:I$19) | E28: =SUMIF($D$6:$D$19,"FY27",J$6:J$19) | F28: =SUMIF($D$6:$D$19,"FY27",K$6:K$19) | G28: =SUMIF($D$6:$D$19,"FY27",L$6:L$19)
B29: FY28 | C29: =COUNTIF(D6:D19,"FY28") | D29: =SUMIF($D$6:$D$19,"FY28",I$6:I$19) | E29: =SUMIF($D$6:$D$19,"FY28",J$6:J$19) | F29: =SUMIF($D$6:$D$19,"FY28",K$6:K$19) | G29: =SUMIF($D$6:$D$19,"FY28",L$6:L$19)
B30: FY29 | C30: =COUNTIF(D6:D19,"FY29") | D30: =SUMIF($D$6:$D$19,"FY29",I$6:I$19) | E30: =SUMIF($D$6:$D$19,"FY29",J$6:J$19) | F30: =SUMIF($D$6:$D$19,"FY29",K$6:K$19) | G30: =SUMIF($D$6:$D$19,"FY29",L$6:L$19)
B31: FY30 | C31: =COUNTIF(D6:D19,"FY30") | D31: =SUMIF($D$6:$D$19,"FY30",I$6:I$19) | E31: =SUMIF($D$6:$D$19,"FY30",J$6:J$19) | F31: =SUMIF($D$6:$D$19,"FY30",K$6:K$19) | G31: =SUMIF($D$6:$D$19,"FY30",L$6:L$19)

Sheet Operating
B2: CONSOLIDATED OPERATING BUILD
B3: Bottom-up: acquired cohort revenue (full-year basis from acquisition year) × organic growth × AI margin ramp
B5: Line | C5: FY26 | D5: FY27 | E5: FY28 | F5: FY29 | G5: FY30
B7: Acquired cohort revenue (€k) | C7: =SUMIF('M&A Schedule'!$D$6:$D$19,"FY26",'M&A Schedule'!$E$6:$E$19) | D7: =C7*(1+Inputs!$C$26)+SUMIF('M&A Schedule'!$D$6:$D$19,"FY27",'M&A Schedule'!$E$6:$E$19) | E7: =D7*(1+Inputs!$C$26)+SUMIF('M&A Schedule'!$D$6:$D$19,"FY28",'M&A Schedule'!$E$6:$E$19) | F7: =E7*(1+Inputs!$C$26)+SUMIF('M&A Schedule'!$D$6:$D$19,"FY29",'M&A Schedule'!$E$6:$E$19) | G7: =F7*(1+Inputs!$C$26)+SUMIF('M&A Schedule'!$D$6:$D$19,"FY30",'M&A Schedule'!$E$6:$E$19)
B9: EBITDA margin: start (pre-uplift) | C9: =Inputs!$C$19 | D9: =Inputs!$C$19 | E9: =Inputs!$C$19 | F9: =Inputs!$C$19 | G9: =Inputs!$C$19
B10: EBITDA margin: AI uplift (years from FY27) | C10: 0 | D10: =MIN(C10+Inputs!$C$27,Inputs!$C$28-Inputs!$C$19) | E10: =MIN(D10+Inputs!$C$27,Inputs!$C$28-Inputs!$C$19) | F10: =MIN(E10+Inputs!$C$27,Inputs!$C$28-Inputs!$C$19) | G10: =MIN(F10+Inputs!$C$27,Inputs!$C$28-Inputs!$C$19)
B11: EBITDA margin: total | C11: =C9+C10 | D11: =D9+D10 | E11: =E9+E10 | F11: =F9+F10 | G11: =G9+G10
B13: Cohort EBITDA (€k) | C13: =C7*C11 | D13: =D7*D11 | E13: =E7*E11 | F13: =F7*F11 | G13: =G7*G11
B15: Holdco SG&A (€k) | C15: =-Inputs!$C$29 | D15: =C15*(1+Inputs!$C$30) | E15: =D15*(1+Inputs!$C$30) | F15: =E15*(1+Inputs!$C$30) | G15: =F15*(1+Inputs!$C$30)
B16: Integration costs (one-time, €k) | C16: =-SUMIF('M&A Schedule'!$D$6:$D$19,"FY26",'M&A Schedule'!$E$6:$E$19)*Inputs!$C$31 | D16: =-SUMIF('M&A Schedule'!$D$6:$D$19,"FY27",'M&A Schedule'!$E$6:$E$19)*Inputs!$C$31 | E16: =-SUMIF('M&A Schedule'!$D$6:$D$19,"FY28",'M&A Schedule'!$E$6:$E$19)*Inputs!$C$31 | F16: =-SUMIF('M&A Schedule'!$D$6:$D$19,"FY29",'M&A Schedule'!$E$6:$E$19)*Inputs!$C$31 | G16: =-SUMIF('M&A Schedule'!$D$6:$D$19,"FY30",'M&A Schedule'!$E$6:$E$19)*Inputs!$C$31
B18: GROUP EBITDA (€k) | C18: =C13+C15+C16 | D18: =D13+D15+D16 | E18: =E13+E15+E16 | F18: =F13+F15+F16 | G18: =G13+G15+G16
B19: Group EBITDA margin | C19: =IFERROR(C18/C7,0) | D19: =IFERROR(D18/D7,0) | E19: =IFERROR(E18/E7,0) | F19: =IFERROR(F18/F7,0) | G19: =IFERROR(G18/G7,0)

Sheet IS
B2: INCOME STATEMENT (EUR '000)
B5: Line | C5: FY26 | D5: FY27 | E5: FY28 | F5: FY29 | G5: FY30
B7: Revenue | C7: =Operating!C7 | D7: =Operating!D7 | E7: =Operating!E7 | F7: =Operating!F7 | G7: =Operating!G7
B8: EBITDA | C8: =Operating!C18 | D8: =Operating!D18 | E8: =Operating!E18 | F8: =Operating!F18 | G8: =Operating!G18
B9: D&A | C9: =-C7*Inputs!$C$32 | D9: =-D7*Inputs!$C$32 | E9: =-E7*Inputs!$C$32 | F9: =-F7*Inputs!$C$32 | G9: =-G7*Inputs!$C$32
B10: EBIT | C10: =C8+C9 | D10: =D8+D9 | E10: =E8+E9 | F10: =F8+F9 | G10: =G8+G9
B11: Interest expense | C11: =-Debt!C11 | D11: =-Debt!D11 | E11: =-Debt!E11 | F11: =-Debt!F11 | G11: =-Debt!G11
B12: EBT | C12: =C10+C11 | D12: =D10+D11 | E12: =E10+E11 | F12: =F10+F11 | G12: =G10+G11
B13: Tax | C13: =IF(C12<0,0,-C12*Inputs!$C$13) | D13: =IF(D12<0,0,-D12*Inputs!$C$13) | E13: =IF(E12<0,0,-E12*Inputs!$C$13) | F13: =IF(F12<0,0,-F12*Inputs!$C$13) | G13: =IF(G12<0,0,-G12*Inputs!$C$13)
B14: NET INCOME | C14: =C12+C13 | D14: =D12+D13 | E14: =E12+E13 | F14: =F12+F13 | G14: =G12+G13
B20: NI (for check) | C20: =C14 | D20: =D14 | E20: =E14 | F20: =F14 | G20: =G14

Sheet BS
B2: BALANCE SHEET (EUR '000)
B3: Simplified for pre-Series-A pitch; full BS to be modeled with detailed WC, PP&E rolls in v2.
B5: Line | C5: FY26 | D5: FY27 | E5: FY28 | F5: FY29 | G5: FY30
B7: Cash & equivalents | C7: =CF!C30 | D7: =CF!D30 | E7: =CF!E30 | F7: =CF!F30 | G7: =CF!G30
B8: Goodwill & intangibles (cum.) | C8: ='M&A Schedule'!D27 | D8: =C8+'M&A Schedule'!D27 | E8: =D8+'M&A Schedule'!E27 | F8: =E8+'M&A Schedule'!F27 | G8: =F8+'M&A Schedule'!G27
B9: Working capital (NWC) | C9: =IS!C7*Inputs!$C$34/365 | D9: =IS!D7*Inputs!$C$34/365 | E9: =IS!E7*Inputs!$C$34/365 | F9: =IS!F7*Inputs!$C$34/365 | G9: =IS!G7*Inputs!$C$34/365
B10: PP&E (cumulative capex - D&A) | C10: =IS!C7*Inputs!$C$33+IS!C9 | D10: =C10+IS!D7*Inputs!$C$33+IS!D9 | E10: =D10+IS!E7*Inputs!$C$33+IS!E9 | F10: =E10+IS!F7*Inputs!$C$33+IS!F9 | G10: =F10+IS!G7*Inputs!$C$33+IS!G9
B25: TOTAL ASSETS | C25: =C7+C8+C9+C10 | D25: =D7+D8+D9+D10 | E25: =E7+E8+E9+E10 | F25: =F7+F8+F9+F10 | G25: =G7+G8+G9+G10
B27: Debt | C27: =Debt!C10 | D27: =Debt!D10 | E27: =Debt!E10 | F27: =Debt!F10 | G27: =Debt!G10
B28: Earnout liability | C28: ='M&A Schedule'!G27 | D28: =C28+'M&A Schedule'!D27*0.5-C28*0.5 | E28: =D28+'M&A Schedule'!E27*0.5-D28*0.5 | F28: =E28+'M&A Schedule'!F27*0.5-E28*0.5 | G28: =F28+'M&A Schedule'!G27*0.5-F28*0.5
B30: Paid-in capital | C30: =Inputs!$C$15+Inputs!$C$16+Inputs!$C$17 | D30: =C30 | E30: =D30 | F30: =E30 | G30: =F30
B31: Retained earnings | C31: =IS!C14 | D31: =C31+IS!D14 | E31: =D31+IS!E14 | F31: =E31+IS!F14 | G31: =F31+IS!G14
B40: TOTAL LIAB + EQUITY | C40: =C27+C28+C30+C31 | D40: =D27+D28+D30+D31 | E40: =E27+E28+E30+E31 | F40: =F27+F28+F30+F31 | G40: =G27+G28+G30+G31

Sheet CF
B2: CASH FLOW STATEMENT (EUR '000)
B5: Net income | C5: =IS!C14 | D5: =IS!D14 | E5: =IS!E14 | F5: =IS!F14 | G5: =IS!G14
B6: + D&A | C6: =-IS!C9 | D6: =-IS!D9 | E6: =-IS!E9 | F6: =-IS!F9 | G6: =-IS!G9
B7: − Δ NWC | C7: =-BS!C9 | D7: =-(BS!D9-BS!C9) | E7: =-(BS!E9-BS!D9) | F7: =-(BS!F9-BS!E9) | G7: =-(BS!G9-BS!F9)
B8: OP CASH FLOW | C8: =C5+C6+C7 | D8: =D5+D6+D7 | E8: =E5+E6+E7 | F8: =F5+F6+F7 | G8: =G5+G6+G7
B10: − Capex | C10: =-IS!C7*Inputs!$C$33 | D10: =-IS!D7*Inputs!$C$33 | E10: =-IS!E7*Inputs!$C$33 | F10: =-IS!F7*Inputs!$C$33 | G10: =-IS!G7*Inputs!$C$33
B11: − Acquisitions (equity portion) | C11: =-'M&A Schedule'!C29 | D11: =-'M&A Schedule'!D29 | E11: =-'M&A Schedule'!E29 | F11: =-'M&A Schedule'!F29 | G11: =-'M&A Schedule'!G29
B12: INVESTING CASH FLOW | C12: =C10+C11 | D12: =D10+D11 | E12: =E10+E11 | F12: =F10+F11 | G12: =G10+G11
B14: + Debt drawings | C14: =Debt!C9 | D14: =Debt!D9 | E14: =Debt!E9 | F14: =Debt!F9 | G14: =Debt!G9
B15: + Equity raised (one-time per round) | C15: =Inputs!$C$15+Inputs!$C$16 | D15: =Inputs!$C$17 | E15: 0 | F15: 0 | G15: 0
B16: FINANCING CASH FLOW | C16: =C14+C15 | D16: =D14+D15 | E16: =E14+E15 | F16: =F14+F15 | G16: =G14+G15
B18: NET CHANGE IN CASH | C18: =C8+C12+C16 | D18: =D8+D12+D16 | E18: =E8+E12+E16 | F18: =F8+F12+F16 | G18: =G8+G12+G16
B29: Opening cash | C29: 0 | D29: =C30 | E29: =D30 | F29: =E30 | G29: =F30
B30: CLOSING CASH | C30: =C29+C18 | D30: =D29+D18 | E30: =E29+E18 | F30: =F29+F18 | G30: =G29+G18

Sheet Debt
B2: ACQUISITION DEBT SCHEDULE
B3: Simplified: each year's acquisition debt assumed drawn at start of year, interest accrued at year-end.
B5: Line | C5: FY26 | D5: FY27 | E5: FY28 | F5: FY29 | G5: FY30
B7: New debt drawn (€k) | C7: ='M&A Schedule'!C28 | D7: ='M&A Schedule'!D28 | E7: ='M&A Schedule'!E28 | F7: ='M&A Schedule'!F28 | G7: ='M&A Schedule'!G28
B8: Opening debt balance | C8: 0 | D8: =C10 | E8: =D10 | F8: =E10 | G8: =F10
B9: + New drawings | C9: =C7 | D9: =D7 | E9: =E7 | F9: =F7 | G9: =G7
B10: CLOSING debt balance | C10: =C8+C9 | D10: =D8+D9 | E10: =E8+E9 | F10: =F8+F9 | G10: =G8+G9
B11: Interest expense (€k) | C11: =AVERAGE(C8,C10)*Inputs!$C$22 | D11: =AVERAGE(D8,D10)*Inputs!$C$22 | E11: =AVERAGE(E8,E10)*Inputs!$C$22 | F11: =AVERAGE(F8,F10)*Inputs!$C$22 | G11: =AVERAGE(G8,G10)*Inputs!$C$22
B13: Net debt / EBITDA | C13: =IFERROR(C10/IS!C8,0) | D13: =IFERROR(D10/IS!D8,0) | E13: =IFERROR(E10/IS!E8,0) | F13: =IFERROR(F10/IS!F8,0) | G13: =IFERROR(G10/IS!G8,0)

Sheet Scenarios
B2: SCENARIO MATRIX
B3: Toggle scenario on Cover sheet (cell C16): 1=Base, 2=Bull, 3=Bear
B5: Driver | C5: Base | D5: Bull | E5: Bear
B6: Entry EV/EBITDA multiple | C6: 4.5 | D6: 3.8 | E6: 5.5
B7: Exit EV/EBITDA multiple (Y5) | C7: 10 | D7: 13 | E7: 7
B8: Organic growth | C8: 0.08 | D8: 0.14 | E8: 0.03
B9: EBITDA AI uplift per year | C9: 0.04 | D9: 0.06 | E9: 0.02
B10: Mature EBITDA margin cap | C10: 0.3 | D10: 0.38 | E10: 0.22
B11: Deal cadence (deals/yr avg) | C11: 2.8 | D11: 3.4 | E11: 2
B12: Holdco SG&A growth/yr | C12: 0.2 | D12: 0.15 | E12: 0.25

Sheet Sensitivity
B2: SENSITIVITY: EXIT MoIC
B3: Money-on-Money (MoIC) at exit Y5: equity invested → exit equity value
B5: Exit multiple ↓ × Organic growth → | C5: 0.03 | D5: 0.05 | E5: 0.08 | F5: 0.11 | G5: 0.14
B6: 7 | C6: 1.3539207 | D6: 1.5192977 | E6: 1.7857143 | F6: 2.075282 | G6: 2.3893046
B7: 8.5 | C7: 1.7971078 | D7: 1.9979228 | E7: 2.3214286 | F7: 2.6730465 | G7: 3.0543597
B8: 10 | C8: 2.2402949 | D8: 2.4765478 | E8: 2.8571429 | F8: 3.270811 | G8: 3.7194148
B9: 11.5 | C9: 2.683482 | D9: 2.9551728 | E9: 3.3928571 | F9: 3.8685755 | G9: 4.3844699
B10: 13 | C10: 3.1266691 | D10: 3.4337978 | E10: 3.9285714 | F10: 4.46634 | G10: 5.0495249
B12: Reading: green ≥ 3x MoIC; yellow 2–3x; red < 2x

Sheet 100-Day Plan
B2: 100-DAY EXECUTION PLAN — FOUNDER + 2 FTE LEAN SEED
B3: Daily owner: Founder unless stated. Mark Status as Planned / In-progress / Done. Color-code by workstream.
B5: Day | C5: Phase | D5: Workstream | E5: Action / Milestone | F5: Owner | G5: Deliverable | H5: Status
B6: 1 | C6: Foundation | D6: Legal | E6: Incorporate Cyprus holdco (Ltd) + open bank account | F6: Founder + lawyer | G6: Cert of incorp + IBAN | H6: Planned
B7: 2 | C7: Foundation | D7: Legal | E7: Draft & sign cofounder agreement, share split, vesting (4yr / 1yr cliff) | F7: Founder + cofounder lawyer | G7: Signed shareholders agreement | H7: Planned
B8: 3 | C8: Foundation | D8: Capital | E8: Close €250k seed (founders + 2-3 angels) | F8: Founder | G8: Wire receipt + SAFE/equity docs | H8: Planned
B9: 4 | C9: Foundation | D9: Branding | E9: Lock company name, trademark search in PL/IT/CY + domain & socials | F9: Cofounder (Ops) | G9: Trademarks filed, domains acquired | H9: Planned
B10: 5 | C10: Foundation | D10: Hiring | E10: Post job ads: M&A Associate (PL-based) + Engineer (remote) | F10: Founder | G10: 2 job posts live, ATS in place | H10: Planned
B11: 7 | C11: Foundation | D11: Tools | E11: Set up Notion/Linear, Slack, Google Workspace, HubSpot CRM | F11: Cofounder | G11: All accounts live + onboarding playbook | H11: Planned
B12: 10 | C12: Foundation | D12: Investors | E12: Build pre-Series-A target list (40 funds) + warm intros | F12: Founder | G12: Investor CRM with 40 targets | H12: Planned
B13: 15 | C13: Foundation | D13: Branding | E13: Launch website + LinkedIn company page + investor one-pager | F13: Cofounder | G13: ledger.co live + 1-pager PDF | H13: Planned
B14: 16 | C14: Sourcing | D14: M&A | E14: Build PL target longlist: 80–120 small accounting firms + niche software | F14: M&A Associate | G14: PL longlist v1 | H14: Planned
B15: 18 | C15: Sourcing | D15: Market | E15: Engage Polish accounting association (KIDP) — partnership talks | F15: Founder | G15: Meeting set with KIDP exec | H15: Planned
B16: 20 | C16: Sourcing | D16: M&A | E16: Mailer + cold-call campaign: 60 owners contacted in PL | F16: M&A Associate | G16: 60 owner touchpoints logged | H16: Planned
B17: 22 | C17: Sourcing | D17: Tech | E17: Build internal due-diligence template (financial + tech + customer) | F17: Founder + auditor | G17: DD checklist + data room template | H17: Planned
... B49: 100 | C49: Scale | D49: Comms | E49: Founder LP / angel update: 2 deals closed, Series A signed, IT pipeline open | F49: Founder | G49: Update email + Loom video | H49: Planned

Sheet Outputs
B2: KPI DASHBOARD
B5: KPI | C5: FY26 | D5: FY27 | E5: FY28 | F5: FY29 | G5: FY30
B6: Revenue (€k) | C6: =IS!C7 | D6: =IS!D7 | E6: =IS!E7 | F6: =IS!F7 | G6: =IS!G7
B7: EBITDA (€k) | C7: =IS!C8 | D7: =IS!D8 | E7: =IS!E8 | F7: =IS!F8 | G7: =IS!G8
B8: EBITDA margin | C8: =IFERROR(IS!C8/IS!C7,0) | D8: =IFERROR(IS!D8/IS!D7,0) | E8: =IFERROR(IS!E8/IS!E7,0) | F8: =IFERROR(IS!F8/IS!F7,0) | G8: =IFERROR(IS!G8/IS!G7,0)
B9: Net income (€k) | C9: =IS!C14 | D9: =IS!D14 | E9: =IS!E14 | F9: =IS!F14 | G9: =IS!G14
B10: # deals YTD (cumulative) | C10: ='M&A Schedule'!C27 | D10: ='M&A Schedule'!D27 | E10: ='M&A Schedule'!E27 | F10: ='M&A Schedule'!F27 | G10: ='M&A Schedule'!G27
B11: Cumulative invested (€k) | C11: =SUM('M&A Schedule'!$D$27:C27) | D11: =SUM('M&A Schedule'!$D$27:D27) | E11: =SUM('M&A Schedule'!$D$27:E27) | F11: =SUM('M&A Schedule'!$D$27:F27) | G11: =SUM('M&A Schedule'!$D$27:G27)
B12: Closing cash (€k) | C12: =CF!C30 | D12: =CF!D30 | E12: =CF!E30 | F12: =CF!F30 | G12: =CF!G30
B13: Net debt / EBITDA | C13: =IFERROR(Debt!C10/IS!C8,0) | D13: =IFERROR(Debt!D10/IS!D8,0) | E13: =IFERROR(Debt!E10/IS!E8,0) | F13: =IFERROR(Debt!F10/IS!F8,0) | G13: =IFERROR(Debt!G10/IS!G8,0)
B16: EXIT VALUATION — YEAR 5 (Base case)
B17: FY30 EBITDA (€k) | C17: =IS!G8
B18: Exit EV/EBITDA multiple | C18: =Inputs!$C$23
B19: Enterprise Value at exit (€k) | C19: =C17*C18
B20: − Net debt (€k) | C20: =-Debt!G10
B21: Equity value at exit (€k) | C21: =C19+C20
B22: Total equity invested (€k) | C22: =Inputs!$C$15+Inputs!$C$16+Inputs!$C$17
B23: MoIC (Money-on-Money) | C23: =C21/C22
B24: IRR (approx, 5-yr) | C24: =(C21/C22)^(1/5)-1

Sheet Sources
B2: DATA SOURCES & REFERENCES
B4: Category | C4: Source
B5: Visma history & PE | C5: https://hgcapital.com/portfolio/visma
B6: Visma 2023 €19B secondary | C6: https://www.visma.com/news/visma-attracts-new-investors-for-further-international-expansion-in-a-transaction-valuing-the-company-at-eur-19-billion
B7: Visma 2020 Warburg/TPG | C7: https://warburgpincus.com/2020/08/24/new-investment-in-visma-valued-at-us12-2-billion-in-the-worlds-largest-ever-software-buyout
B8: Visma annual report 2024 | C8: https://www.visma.com/annualreport/2024
B9: Visma M&A playbook podcast | C9: https://www.mascience.com/podcast/how-to-build-a-global-m-a-machine-with-local-expertise
B10: Visma Fiscozen (Italy 2024) | C10: Internal: Visma news release — Italian tax advisory acquisition
B11: Visma Holded (Spain 2021) | C11: Visma's Spanish AI accounting platform — relevant comparable
B12: Constellation Software | C12: https://www.csisoftware.com/operating-groups
B13: Topicus.com spin-out | C13: https://topicus.com/news/constellation-software-inc-completes-spin-out-of-topicuscom-inc
B14: Software valuation multiples | C14: https://aventis-advisors.com/software-valuation-multiples
B15: Constellation comp analysis | C15: https://rollupeurope.com/p/utm-source-rss-utm-medium-rss-utm-campaign-boss-your-comps-pt-3-do-software-rollups-deserve-constell
... B22: Spanish AI accounting category | C22: Holded, Anfix, Quipu, Contasimple, Xolo — references
